2020-07-20 18:10:16,320 - App.Api.moduleOpt - ERROR - moduleOpt  - 59 - 'Response' object has no attribute 'id'
Traceback (most recent call last):
  File "/home/mi/Fan_Platform/App/Api/moduleOpt.py", line 54, in get
    in m]
  File "/home/mi/Fan_Platform/App/Api/moduleOpt.py", line 53, in <listcomp>
    for i
AttributeError: 'Response' object has no attribute 'id'
2020-07-20 18:15:33,810 - App.Api.moduleOpt - ERROR - moduleOpt  - 58 - 'Response' object has no attribute 'id'
Traceback (most recent call last):
  File "/home/mi/Fan_Platform/App/Api/moduleOpt.py", line 53, in get
    for i in m]
  File "/home/mi/Fan_Platform/App/Api/moduleOpt.py", line 53, in <listcomp>
    for i in m]
AttributeError: 'Response' object has no attribute 'id'
2020-07-20 18:16:21,967 - App.Api.moduleOpt - ERROR - moduleOpt  - 59 - 'Response' object has no attribute 'id'
Traceback (most recent call last):
  File "/home/mi/Fan_Platform/App/Api/moduleOpt.py", line 54, in get
    for i in m]
  File "/home/mi/Fan_Platform/App/Api/moduleOpt.py", line 54, in <listcomp>
    for i in m]
AttributeError: 'Response' object has no attribute 'id'
2020-07-20 18:17:24,727 - App.Api.moduleOpt - ERROR - moduleOpt  - 59 - 'Response' object has no attribute 'module_name'
Traceback (most recent call last):
  File "/home/mi/Fan_Platform/App/Api/moduleOpt.py", line 54, in get
    for i in m]
  File "/home/mi/Fan_Platform/App/Api/moduleOpt.py", line 54, in <listcomp>
    for i in m]
AttributeError: 'Response' object has no attribute 'module_name'
2020-07-20 18:17:51,288 - App.Api.moduleOpt - ERROR - moduleOpt  - 59 - 'Response' object has no attribute 'id'
Traceback (most recent call last):
  File "/home/mi/Fan_Platform/App/Api/moduleOpt.py", line 54, in get
    for i in m]
  File "/home/mi/Fan_Platform/App/Api/moduleOpt.py", line 54, in <listcomp>
    for i in m]
AttributeError: 'Response' object has no attribute 'id'
2020-07-20 18:22:25,272 - App.Api.moduleOpt - ERROR - moduleOpt  - 62 - 'Response' object has no attribute 'id'
Traceback (most recent call last):
  File "/home/mi/Fan_Platform/App/Api/moduleOpt.py", line 57, in get
    for i in m]
  File "/home/mi/Fan_Platform/App/Api/moduleOpt.py", line 57, in <listcomp>
    for i in m]
AttributeError: 'Response' object has no attribute 'id'
2020-07-20 18:22:48,689 - App.Api.moduleOpt - ERROR - moduleOpt  - 62 - 'Response' object has no attribute 'id'
Traceback (most recent call last):
  File "/home/mi/Fan_Platform/App/Api/moduleOpt.py", line 57, in get
    for i in m]
  File "/home/mi/Fan_Platform/App/Api/moduleOpt.py", line 57, in <listcomp>
    for i in m]
AttributeError: 'Response' object has no attribute 'id'
2020-07-20 18:23:03,538 - App.Api.moduleOpt - ERROR - moduleOpt  - 62 - 'Response' object has no attribute 'id'
Traceback (most recent call last):
  File "/home/mi/Fan_Platform/App/Api/moduleOpt.py", line 57, in get
    for i in m]
  File "/home/mi/Fan_Platform/App/Api/moduleOpt.py", line 57, in <listcomp>
    for i in m]
AttributeError: 'Response' object has no attribute 'id'
2020-07-20 18:23:17,809 - App.Api.moduleOpt - ERROR - moduleOpt  - 62 - 'Response' object has no attribute 'id'
Traceback (most recent call last):
  File "/home/mi/Fan_Platform/App/Api/moduleOpt.py", line 57, in get
    for i in m]
  File "/home/mi/Fan_Platform/App/Api/moduleOpt.py", line 57, in <listcomp>
    for i in m]
AttributeError: 'Response' object has no attribute 'id'
2020-07-20 18:23:20,865 - App.Api.moduleOpt - ERROR - moduleOpt  - 62 - 'Response' object has no attribute 'id'
Traceback (most recent call last):
  File "/home/mi/Fan_Platform/App/Api/moduleOpt.py", line 57, in get
    for i in m]
  File "/home/mi/Fan_Platform/App/Api/moduleOpt.py", line 57, in <listcomp>
    for i in m]
AttributeError: 'Response' object has no attribute 'id'
2020-07-20 18:23:38,854 - App.Api.moduleOpt - ERROR - moduleOpt  - 62 - 'Response' object has no attribute 'id'
Traceback (most recent call last):
  File "/home/mi/Fan_Platform/App/Api/moduleOpt.py", line 57, in get
    for i in m]
  File "/home/mi/Fan_Platform/App/Api/moduleOpt.py", line 57, in <listcomp>
    for i in m]
AttributeError: 'Response' object has no attribute 'id'
2020-07-20 18:31:16,419 - App.Api.moduleOpt - ERROR - moduleOpt  - 62 - 'Response' object has no attribute 'id'
Traceback (most recent call last):
  File "/home/mi/Fan_Platform/App/Api/moduleOpt.py", line 57, in get
    for i in m]
  File "/home/mi/Fan_Platform/App/Api/moduleOpt.py", line 57, in <listcomp>
    for i in m]
AttributeError: 'Response' object has no attribute 'id'
2020-07-20 18:32:08,046 - App.Api.moduleOpt - ERROR - moduleOpt  - 62 - exceptions must derive from BaseException
Traceback (most recent call last):
  File "/home/mi/Fan_Platform/App/Api/moduleOpt.py", line 44, in get
    m = Module.getObj(mid)
  File "/home/mi/Fan_Platform/Model/Models.py", line 33, in getObj
    raise jsonify(dict(code=1, err="id錯誤或不存在"))
TypeError: exceptions must derive from BaseException
2020-07-20 18:33:10,906 - App.Api.moduleOpt - ERROR - moduleOpt  - 62 - 404 Not Found: The requested URL was not found on the server. If you entered the URL manually please check your spelling and try again.
Traceback (most recent call last):
  File "/home/mi/Fan_Platform/App/Api/moduleOpt.py", line 44, in get
    m = Module.query.get_or_404(mid)
  File "/home/mi/flask/lib/python3.6/site-packages/flask_sqlalchemy/__init__.py", line 424, in get_or_404
    abort(404, description=description)
  File "/home/mi/flask/lib/python3.6/site-packages/werkzeug/exceptions.py", line 822, in abort
    return _aborter(status, *args, **kwargs)
  File "/home/mi/flask/lib/python3.6/site-packages/werkzeug/exceptions.py", line 807, in __call__
    raise self.mapping[code](*args, **kwargs)
werkzeug.exceptions.NotFound: 404 Not Found: The requested URL was not found on the server. If you entered the URL manually please check your spelling and try again.
2020-07-20 18:35:16,661 - App.Api.moduleOpt - ERROR - moduleOpt  - 62 - 'Response' object has no attribute 'id'
Traceback (most recent call last):
  File "/home/mi/Fan_Platform/App/Api/moduleOpt.py", line 57, in get
    for i in m]
  File "/home/mi/Fan_Platform/App/Api/moduleOpt.py", line 57, in <listcomp>
    for i in m]
AttributeError: 'Response' object has no attribute 'id'
2020-07-20 18:35:43,732 - App.Api.moduleOpt - ERROR - moduleOpt  - 62 - 'Response' object has no attribute 'id'
Traceback (most recent call last):
  File "/home/mi/Fan_Platform/App/Api/moduleOpt.py", line 57, in get
    for i in m]
  File "/home/mi/Fan_Platform/App/Api/moduleOpt.py", line 57, in <listcomp>
    for i in m]
AttributeError: 'Response' object has no attribute 'id'
2020-07-20 18:37:09,325 - App.Api.moduleOpt - ERROR - moduleOpt  - 62 - ??? Unknown Error: None
Traceback (most recent call last):
  File "/home/mi/Fan_Platform/App/Api/moduleOpt.py", line 44, in get
    m = Module.getObj(mid)
  File "/home/mi/Fan_Platform/Model/Models.py", line 34, in getObj
    abort(Response(dict(code=1, err="id錯誤或不存在"), 404))
  File "/home/mi/flask/lib/python3.6/site-packages/flask_restful/__init__.py", line 32, in abort
    original_flask_abort(http_status_code)
  File "/home/mi/flask/lib/python3.6/site-packages/werkzeug/exceptions.py", line 822, in abort
    return _aborter(status, *args, **kwargs)
  File "/home/mi/flask/lib/python3.6/site-packages/werkzeug/exceptions.py", line 804, in __call__
    raise HTTPException(response=code)
werkzeug.exceptions.HTTPException: ??? Unknown Error: None
2020-07-20 18:38:06,305 - App.Api.moduleOpt - ERROR - moduleOpt  - 62 - ??? Unknown Error: None
Traceback (most recent call last):
  File "/home/mi/Fan_Platform/App/Api/moduleOpt.py", line 44, in get
    m = Module.getObj(mid)
  File "/home/mi/Fan_Platform/Model/Models.py", line 33, in getObj
    abort(Response(dict(code=1, err="id錯誤或不存在"), 404))
  File "/home/mi/flask/lib/python3.6/site-packages/werkzeug/exceptions.py", line 822, in abort
    return _aborter(status, *args, **kwargs)
  File "/home/mi/flask/lib/python3.6/site-packages/werkzeug/exceptions.py", line 804, in __call__
    raise HTTPException(response=code)
werkzeug.exceptions.HTTPException: ??? Unknown Error: None
2020-07-20 18:38:32,171 - App.Api.moduleOpt - ERROR - moduleOpt  - 62 - ??? Unknown Error: None
Traceback (most recent call last):
  File "/home/mi/Fan_Platform/App/Api/moduleOpt.py", line 44, in get
    m = Module.getObj(mid)
  File "/home/mi/Fan_Platform/Model/Models.py", line 34, in getObj
    abort(Response(dict(code=1, err="id錯誤或不存在"), 404))
  File "/home/mi/flask/lib/python3.6/site-packages/werkzeug/exceptions.py", line 822, in abort
    return _aborter(status, *args, **kwargs)
  File "/home/mi/flask/lib/python3.6/site-packages/werkzeug/exceptions.py", line 804, in __call__
    raise HTTPException(response=code)
werkzeug.exceptions.HTTPException: ??? Unknown Error: None
2020-07-20 18:42:59,477 - App.Api.moduleOpt - ERROR - moduleOpt  - 62 - ??? Unknown Error: None
Traceback (most recent call last):
  File "/home/mi/Fan_Platform/App/Api/moduleOpt.py", line 44, in get
    m = Module.query.get_or_404(mid)
  File "/home/mi/Fan_Platform/comments/MyBaseQueryOpt.py", line 33, in get_or_404
    abort(Response(err_msg, 404))
  File "/home/mi/flask/lib/python3.6/site-packages/werkzeug/exceptions.py", line 822, in abort
    return _aborter(status, *args, **kwargs)
  File "/home/mi/flask/lib/python3.6/site-packages/werkzeug/exceptions.py", line 804, in __call__
    raise HTTPException(response=code)
werkzeug.exceptions.HTTPException: ??? Unknown Error: None
2020-07-20 18:43:25,346 - App.Api.moduleOpt - ERROR - moduleOpt  - 62 - ??? Unknown Error: None
Traceback (most recent call last):
  File "/home/mi/Fan_Platform/App/Api/moduleOpt.py", line 44, in get
    m = Module.query.get_or_404(mid)
  File "/home/mi/Fan_Platform/comments/MyBaseQueryOpt.py", line 34, in get_or_404
    abort(Response(err_msg, 404))
  File "/home/mi/flask/lib/python3.6/site-packages/werkzeug/exceptions.py", line 822, in abort
    return _aborter(status, *args, **kwargs)
  File "/home/mi/flask/lib/python3.6/site-packages/werkzeug/exceptions.py", line 804, in __call__
    raise HTTPException(response=code)
werkzeug.exceptions.HTTPException: ??? Unknown Error: None
2020-07-20 18:44:33,785 - App.Api.moduleOpt - ERROR - moduleOpt  - 62 - ??? Unknown Error: None
Traceback (most recent call last):
  File "/home/mi/Fan_Platform/App/Api/moduleOpt.py", line 44, in get
    Module.query.get_or_405(mid)
  File "/home/mi/Fan_Platform/comments/MyBaseQueryOpt.py", line 33, in get_or_405
    abort(Response(err_msg, 404))
  File "/home/mi/flask/lib/python3.6/site-packages/werkzeug/exceptions.py", line 822, in abort
    return _aborter(status, *args, **kwargs)
  File "/home/mi/flask/lib/python3.6/site-packages/werkzeug/exceptions.py", line 804, in __call__
    raise HTTPException(response=code)
werkzeug.exceptions.HTTPException: ??? Unknown Error: None
2020-07-20 18:44:54,006 - App.Api.moduleOpt - ERROR - moduleOpt  - 62 - ??? Unknown Error: None
Traceback (most recent call last):
  File "/home/mi/Fan_Platform/App/Api/moduleOpt.py", line 44, in get
    m = Module.query.get_or_405(mid)
  File "/home/mi/Fan_Platform/comments/MyBaseQueryOpt.py", line 34, in get_or_405
    abort(Response(err_msg, 404))
  File "/home/mi/flask/lib/python3.6/site-packages/werkzeug/exceptions.py", line 822, in abort
    return _aborter(status, *args, **kwargs)
  File "/home/mi/flask/lib/python3.6/site-packages/werkzeug/exceptions.py", line 804, in __call__
    raise HTTPException(response=code)
werkzeug.exceptions.HTTPException: ??? Unknown Error: None
2020-07-20 18:48:03,231 - App.Api.moduleOpt - ERROR - moduleOpt  - 62 - 404 Not Found: {"code": 1, "err": "id\u932f\u8aa4\u6216\u4e0d\u5b58\u5728"}
Traceback (most recent call last):
  File "/home/mi/Fan_Platform/App/Api/moduleOpt.py", line 44, in get
    m = Module.query.get_or_405(mid)
  File "/home/mi/Fan_Platform/comments/MyBaseQueryOpt.py", line 34, in get_or_405
    abort(404,err_msg)
  File "/home/mi/flask/lib/python3.6/site-packages/werkzeug/exceptions.py", line 822, in abort
    return _aborter(status, *args, **kwargs)
  File "/home/mi/flask/lib/python3.6/site-packages/werkzeug/exceptions.py", line 807, in __call__
    raise self.mapping[code](*args, **kwargs)
werkzeug.exceptions.NotFound: 404 Not Found: {"code": 1, "err": "id\u932f\u8aa4\u6216\u4e0d\u5b58\u5728"}
2020-07-20 18:48:23,110 - App.Api.moduleOpt - ERROR - moduleOpt  - 62 - 404 Not Found: {'code': 1, 'err': 'id錯誤或不存在'}
Traceback (most recent call last):
  File "/home/mi/Fan_Platform/App/Api/moduleOpt.py", line 44, in get
    m = Module.query.get_or_405(mid)
  File "/home/mi/Fan_Platform/comments/MyBaseQueryOpt.py", line 34, in get_or_405
    abort(404,err_msg)
  File "/home/mi/flask/lib/python3.6/site-packages/werkzeug/exceptions.py", line 822, in abort
    return _aborter(status, *args, **kwargs)
  File "/home/mi/flask/lib/python3.6/site-packages/werkzeug/exceptions.py", line 807, in __call__
    raise self.mapping[code](*args, **kwargs)
werkzeug.exceptions.NotFound: 404 Not Found: {'code': 1, 'err': 'id錯誤或不存在'}
2020-07-20 18:48:41,399 - App.Api.moduleOpt - ERROR - moduleOpt  - 62 - 404 Not Found: id錯誤或不存在
Traceback (most recent call last):
  File "/home/mi/Fan_Platform/App/Api/moduleOpt.py", line 44, in get
    m = Module.query.get_or_405(mid)
  File "/home/mi/Fan_Platform/comments/MyBaseQueryOpt.py", line 34, in get_or_405
    abort(404,err_msg)
  File "/home/mi/flask/lib/python3.6/site-packages/werkzeug/exceptions.py", line 822, in abort
    return _aborter(status, *args, **kwargs)
  File "/home/mi/flask/lib/python3.6/site-packages/werkzeug/exceptions.py", line 807, in __call__
    raise self.mapping[code](*args, **kwargs)
werkzeug.exceptions.NotFound: 404 Not Found: id錯誤或不存在
2020-07-20 18:52:02,215 - /home/mi/Fan_Platform/App/Api/userOpt.py - ERROR - userOpt  - 132 - type object 'User' has no attribute 'get_or_405'
Traceback (most recent call last):
  File "/home/mi/Fan_Platform/App/Api/userOpt.py", line 120, in get
    user = [User.get_or_405(user_id)]
AttributeError: type object 'User' has no attribute 'get_or_405'
2020-07-20 18:52:12,699 - /home/mi/Fan_Platform/App/Api/userOpt.py - ERROR - userOpt  - 132 - type object 'User' has no attribute 'get_or_405'
Traceback (most recent call last):
  File "/home/mi/Fan_Platform/App/Api/userOpt.py", line 120, in get
    user = [User.get_or_405(user_id)]
AttributeError: type object 'User' has no attribute 'get_or_405'
2020-07-20 18:53:13,984 - /home/mi/Fan_Platform/App/Api/userOpt.py - ERROR - userOpt  - 132 - 404 Not Found: id錯誤或不存在
Traceback (most recent call last):
  File "/home/mi/Fan_Platform/App/Api/userOpt.py", line 120, in get
    user = [User.query.get_or_405(user_id)]
  File "/home/mi/Fan_Platform/comments/MyBaseQueryOpt.py", line 28, in get_or_405
    abort(404,err_msg)
  File "/home/mi/flask/lib/python3.6/site-packages/werkzeug/exceptions.py", line 822, in abort
    return _aborter(status, *args, **kwargs)
  File "/home/mi/flask/lib/python3.6/site-packages/werkzeug/exceptions.py", line 807, in __call__
    raise self.mapping[code](*args, **kwargs)
werkzeug.exceptions.NotFound: 404 Not Found: id錯誤或不存在
2020-07-20 18:54:11,233 - /home/mi/Fan_Platform/App/Api/userOpt.py - ERROR - userOpt  - 132 - 404 Not Found: id錯誤或不存在
Traceback (most recent call last):
  File "/home/mi/Fan_Platform/App/Api/userOpt.py", line 120, in get
    user = [User.query.get_or_405(user_id)]
  File "/home/mi/Fan_Platform/comments/MyBaseQueryOpt.py", line 28, in get_or_405
    abort(404,err_msg)
  File "/home/mi/flask/lib/python3.6/site-packages/werkzeug/exceptions.py", line 822, in abort
    return _aborter(status, *args, **kwargs)
  File "/home/mi/flask/lib/python3.6/site-packages/werkzeug/exceptions.py", line 807, in __call__
    raise self.mapping[code](*args, **kwargs)
werkzeug.exceptions.NotFound: 404 Not Found: id錯誤或不存在
2020-07-20 18:54:18,607 - /home/mi/Fan_Platform/App/Api/userOpt.py - ERROR - userOpt  - 132 - 404 Not Found: id錯誤或不存在
Traceback (most recent call last):
  File "/home/mi/Fan_Platform/App/Api/userOpt.py", line 120, in get
    user = [User.query.get_or_405(user_id)]
  File "/home/mi/Fan_Platform/comments/MyBaseQueryOpt.py", line 28, in get_or_405
    abort(404,err_msg)
  File "/home/mi/flask/lib/python3.6/site-packages/werkzeug/exceptions.py", line 822, in abort
    return _aborter(status, *args, **kwargs)
  File "/home/mi/flask/lib/python3.6/site-packages/werkzeug/exceptions.py", line 807, in __call__
    raise self.mapping[code](*args, **kwargs)
werkzeug.exceptions.NotFound: 404 Not Found: id錯誤或不存在
2020-07-20 19:08:02,577 - /home/mi/Fan_Platform/App/Api/userOpt.py - ERROR - userOpt  - 146 - type object 'User' has no attribute 'querty'
Traceback (most recent call last):
  File "/home/mi/Fan_Platform/App/Api/userOpt.py", line 142, in delete
    user = User.querty.get_or_405(id)
AttributeError: type object 'User' has no attribute 'querty'
2020-07-20 19:08:24,313 - /home/mi/Fan_Platform/App/Api/userOpt.py - ERROR - userOpt  - 146 - delete() missing 1 required positional argument: 'id'
Traceback (most recent call last):
  File "/home/mi/Fan_Platform/App/Api/userOpt.py", line 143, in delete
    user.delete()
TypeError: delete() missing 1 required positional argument: 'id'
2020-07-20 19:18:21,048 - /home/mi/Fan_Platform/App/Api/userOpt.py - ERROR - userOpt  - 133 - type object 'User' has no attribute 'querty'
Traceback (most recent call last):
  File "/home/mi/Fan_Platform/App/Api/userOpt.py", line 121, in get
    user = User.get(user_id)
  File "/home/mi/Fan_Platform/Model/Models.py", line 34, in get
    obj = cls.querty.get_or_405(id)
AttributeError: type object 'User' has no attribute 'querty'
2020-07-20 19:18:42,042 - /home/mi/Fan_Platform/App/Api/userOpt.py - ERROR - userOpt  - 133 - 'User' object is not iterable
Traceback (most recent call last):
  File "/home/mi/Fan_Platform/App/Api/userOpt.py", line 128, in get
    in user]
TypeError: 'User' object is not iterable
2020-07-20 19:19:09,466 - /home/mi/Fan_Platform/App/Api/userOpt.py - ERROR - userOpt  - 133 - 'User' object is not iterable
Traceback (most recent call last):
  File "/home/mi/Fan_Platform/App/Api/userOpt.py", line 128, in get
    in user]
TypeError: 'User' object is not iterable
2020-07-20 19:19:30,441 - /home/mi/Fan_Platform/App/Api/userOpt.py - ERROR - userOpt  - 133 - 'User' object is not iterable
Traceback (most recent call last):
  File "/home/mi/Fan_Platform/App/Api/userOpt.py", line 128, in get
    in user]
TypeError: 'User' object is not iterable
2020-07-20 19:20:21,391 - /home/mi/Fan_Platform/App/Api/userOpt.py - ERROR - userOpt  - 133 - 404 Not Found: id錯誤或不存在
Traceback (most recent call last):
  File "/home/mi/Fan_Platform/App/Api/userOpt.py", line 121, in get
    user = [User.get(user_id)]
  File "/home/mi/Fan_Platform/Model/Models.py", line 34, in get
    obj = cls.query.get_or_405(id)
  File "/home/mi/Fan_Platform/comments/MyBaseQueryOpt.py", line 26, in get_or_405
    abort(404, err_msg)
  File "/home/mi/flask/lib/python3.6/site-packages/werkzeug/exceptions.py", line 822, in abort
    return _aborter(status, *args, **kwargs)
  File "/home/mi/flask/lib/python3.6/site-packages/werkzeug/exceptions.py", line 807, in __call__
    raise self.mapping[code](*args, **kwargs)
werkzeug.exceptions.NotFound: 404 Not Found: id錯誤或不存在
